<?xml version="1.0"?>
<robot name="UR5">
  <link name="base_link">
    <visual>
      <origin xyz="0.000087 0.004519 0.003002" rpy="0 0 0"/>
      <geometry>
        <mesh filename="stl_files/base.stl" scale="0.001 0.001 0.001"/>
      </geometry>
    </visual>
  </link>
  <link name="shoulder_link">
    <visual>
      <origin xyz="0.001796 -0.006351 0.065200" rpy="0 0 0"/>
      <geometry>
        <mesh filename="stl_files/shoulder.stl" scale="0.001 0.001 0.001"/>
      </geometry>
    </visual>
  </link>
  <link name="upper_arm_link">
    <visual>
      <origin xyz="-0.014360 0.021756 0.059746" rpy="0 0 0"/>
      <geometry>
        <mesh filename="stl_files/upperarm.stl" scale="0.001 0.001 0.001"/>
      </geometry>
    </visual>
  </link>
  <link name="forearm_link">
    <visual>
      <origin xyz="0.003083 -0.020332 0.057986" rpy="0 0 0"/>
      <geometry>
        <mesh filename="stl_files/forearm.stl" scale="0.001 0.001 0.001"/>
      </geometry>
    </visual>
  </link>
  <link name="wrist_1_link">
    <visual>
      <origin xyz="0.000437 -0.090655 0.057176" rpy="0 0 0"/>
      <geometry>
        <mesh filename="stl_files/wrist1.stl" scale="0.001 0.001 0.001"/>
      </geometry>
    </visual>
  </link>
  <link name="wrist_2_link">
    <visual>
      <origin xyz="0.001581 0.057188 -0.093203" rpy="0 0 0"/>
      <geometry>
        <mesh filename="stl_files/wrist2.stl" scale="0.001 0.001 0.001"/>
      </geometry>
    </visual>
  </link>
  <link name="wrist_3_link">
    <visual>
      <geometry>
        <mesh filename="stl_files/wrist3.stl" scale="0.001 0.001 0.001"/>
      </geometry>
    </visual>
  </link>
  <joint name="shoulder_pan_joint" type="revolute">
    <parent link="base_link"/>
    <child link="shoulder_link"/>
    <origin xyz="0 0 0.089159" rpy="0 0 0"/>
    <axis xyz="0 0 1"/>
    <limit lower="-6.2832" upper="6.2832" effort="100" velocity="1"/>
  </joint>
  <joint name="shoulder_lift_joint" type="revolute">
    <parent link="shoulder_link"/>
    <child link="upper_arm_link"/>
    <origin xyz="0 0.135850 0" rpy="0 1.570796 0"/>
    <axis xyz="0 1 0"/>
    <limit lower="-6.2832" upper="6.2832" effort="100" velocity="1"/>
  </joint>
  <joint name="elbow_joint" type="revolute">
    <parent link="upper_arm_link"/>
    <child link="forearm_link"/>
    <origin xyz="0 -0.119700 0.425000" rpy="0 0 0"/>
    <axis xyz="0 1 0"/>
    <limit lower="-3.1416" upper="3.1416" effort="100" velocity="1"/>
  </joint>
  <joint name="wrist_1_joint" type="revolute">
    <parent link="forearm_link"/>
    <child link="wrist_1_link"/>
    <origin xyz="0 0 0.392250" rpy="0 1.570796 0"/>
    <axis xyz="0 1 0"/>
    <limit lower="-6.2832" upper="6.2832" effort="100" velocity="1"/>
  </joint>
  <joint name="wrist_2_joint" type="revolute">
    <parent link="wrist_1_link"/>
    <child link="wrist_2_link"/>
    <origin xyz="0 0.109150 0" rpy="0 0 0"/>
    <axis xyz="0 0 1"/>
    <limit lower="-6.2832" upper="6.2832" effort="100" velocity="1"/>
  </joint>
  <joint name="wrist_3_joint" type="revolute">
    <parent link="wrist_2_link"/>
    <child link="wrist_3_link"/>
    <origin xyz="0 0 0.094650" rpy="0 0 0"/>
    <axis xyz="0 1 0"/>
    <limit lower="-6.2832" upper="6.2832" effort="100" velocity="1"/>
  </joint>
</robot>
