<?xml version="1.0"?>
<robot name="ABB-IRB2400">
  <link name="base_link">
    <visual>
      <origin xyz="0.014336 0.003980 0.000000" rpy="0 0 0"/>
      <geometry>
        <mesh filename="stl_files/base_link.stl" scale="0.001 0.001 0.001"/>
      </geometry>
    </visual>
  </link>
  <link name="link_1">
    <visual>
      <origin xyz="0.000000 0.000000 0.028000" rpy="0 0 0"/>
      <geometry>
        <mesh filename="stl_files/link_1.stl" scale="0.001 0.001 0.001"/>
      </geometry>
    </visual>
  </link>
  <link name="link_2">
    <visual>
      <origin xyz="0.115063 0.034362 -0.096711" rpy="0 0 0"/>
      <geometry>
        <mesh filename="stl_files/link_2.stl" scale="0.001 0.001 0.001"/>
      </geometry>
    </visual>
  </link>
  <link name="link_3">
    <visual>
      <geometry>
        <mesh filename="stl_files/link_3.stl" scale="0.001 0.001 0.001"/>
      </geometry>
    </visual>
  </link>
  <link name="link_4">
    <visual>
      <origin xyz="0.000000 0.000000 0.001015" rpy="0 0 0"/>
      <geometry>
        <mesh filename="stl_files/link_4.stl" scale="0.001 0.001 0.001"/>
      </geometry>
    </visual>
  </link>
  <link name="link_5">
    <visual>
      <geometry>
        <mesh filename="stl_files/link_5.stl" scale="0.001 0.001 0.001"/>
      </geometry>
    </visual>
  </link>
  <link name="link_6">
    <visual>
      <origin xyz="0.131000 0.000000 0.000000" rpy="0 0 0"/>
      <geometry>
        <mesh filename="stl_files/link_6.stl" scale="0.001 0.001 0.001"/>
      </geometry>
    </visual>
  </link>
  <joint name="joint_1" type="revolute">
    <parent link="base_link"/>
    <child link="link_1"/>
    <origin xyz="0.000000 0.000000 0.000000" rpy="0 0 0"/>
    <axis xyz="0.000000 0.000000 1.000000"/>
    <limit lower="-3.1416" upper="3.1416" effort="100" velocity="1"/>
  </joint>
  <joint name="joint_2" type="revolute">
    <parent link="link_1"/>
    <child link="link_2"/>
    <origin xyz="0.100000 0.000000 0.615000" rpy="0 0 0"/>
    <axis xyz="0.000000 1.000000 0.000000"/>
    <limit lower="-1.7453" upper="1.9199" effort="100" velocity="1"/>
  </joint>
  <joint name="joint_3" type="revolute">
    <parent link="link_2"/>
    <child link="link_3"/>
    <origin xyz="0.000000 0.000000 0.705000" rpy="0 0 0"/>
    <axis xyz="0.000000 1.000000 0.000000"/>
    <limit lower="-1.0472" upper="1.1345" effort="100" velocity="1"/>
  </joint>
  <joint name="joint_4" type="revolute">
    <parent link="link_3"/>
    <child link="link_4"/>
    <origin xyz="0.258000 0.000000 0.135000" rpy="0 0 0"/>
    <axis xyz="1.000000 0.000000 0.000000"/>
    <limit lower="-3.4907" upper="3.4907" effort="100" velocity="1"/>
  </joint>
  <joint name="joint_5" type="revolute">
    <parent link="link_4"/>
    <child link="link_5"/>
    <origin xyz="0.497000 0.000000 0.000000" rpy="0 0 0"/>
    <axis xyz="0.000000 1.000000 0.000000"/>
    <limit lower="-2.0944" upper="2.0944" effort="100" velocity="1"/>
  </joint>
  <joint name="joint_6" type="revolute">
    <parent link="link_5"/>
    <child link="link_6"/>
    <origin xyz="0.085000 0.000000 0.000000" rpy="0 0 0"/>
    <axis xyz="1.000000 0.000000 0.000000"/>
    <limit lower="-6.9813" upper="6.9813" effort="100" velocity="1"/>
  </joint>
</robot>
