<?xml version="1.0"?>
<robot name="Meca500-R3">
  <link name="base_link">
    <visual>
      <geometry>
        <mesh filename="stl_files/A0.stl" scale="0.001 0.001 0.001"/>
      </geometry>
    </visual>
  </link>
  <link name="link_1">
    <visual>
      <origin xyz="-0.000494 0.000065 -0.009530" rpy="0 0 0"/>
      <geometry>
        <mesh filename="stl_files/A1.stl" scale="0.001 0.001 0.001"/>
      </geometry>
    </visual>
  </link>
  <link name="link_2">
    <visual>
      <origin xyz="0.000113 -0.000190 0.000586" rpy="0 0 0"/>
      <geometry>
        <mesh filename="stl_files/A2.stl" scale="0.001 0.001 0.001"/>
      </geometry>
    </visual>
  </link>
  <link name="link_3">
    <visual>
      <origin xyz="0.000037 0.000227 -0.002063" rpy="0 0 0"/>
      <geometry>
        <mesh filename="stl_files/A3_4.stl" scale="0.001 0.001 0.001"/>
      </geometry>
    </visual>
  </link>
  <link name="link_4">
    <visual>
      <origin xyz="-0.000155 0.000826 -0.001166" rpy="0 0 0"/>
      <geometry>
        <mesh filename="stl_files/A5.stl" scale="0.001 0.001 0.001"/>
      </geometry>
    </visual>
  </link>
  <link name="link_5">
    <visual>
      <origin xyz="-0.000162 0.000026 -0.001179" rpy="0 0 0"/>
      <geometry>
        <mesh filename="stl_files/A6.stl" scale="0.001 0.001 0.001"/>
      </geometry>
    </visual>
  </link>
  <link name="link_6">
    <visual>
      <origin xyz="0.065795 0.000027 -0.000051" rpy="0.000000 1.329500 0.019800"/>
      <geometry>
        <mesh filename="stl_files/EndEffector.stl" scale="0.001 0.001 0.001"/>
      </geometry>
    </visual>
  </link>
  <joint name="joint_1" type="revolute">
    <parent link="base_link"/>
    <child link="link_1"/>
    <origin xyz="0.000000 0.000000 0.093000" rpy="0 0 0"/>
    <axis xyz="0.000000 0.000000 1.000000"/>
    <limit lower="-3.054" upper="3.054" effort="100" velocity="1"/>
  </joint>
  <joint name="joint_2" type="revolute">
    <parent link="link_1"/>
    <child link="link_2"/>
    <origin xyz="-0.000419 -0.049821 0.036191" rpy="0 0 0"/>
    <axis xyz="0.000000 1.000000 0.000000"/>
    <limit lower="-1.2217" upper="1.5708" effort="100" velocity="1"/>
  </joint>
  <joint name="joint_3" type="revolute">
    <parent link="link_2"/>
    <child link="link_3"/>
    <origin xyz="0.000000 0.000000 0.135000" rpy="0 0 0"/>
    <axis xyz="0.000000 1.000000 0.000000"/>
    <limit lower="-2.3562" upper="1.2217" effort="100" velocity="1"/>
  </joint>
  <joint name="joint_4" type="revolute">
    <parent link="link_3"/>
    <child link="link_4"/>
    <origin xyz="0.062000 0.000000 0.038000" rpy="0 0 0"/>
    <axis xyz="1.000000 0.000000 0.000000"/>
    <limit lower="-2.9671" upper="2.9671" effort="100" velocity="1"/>
  </joint>
  <joint name="joint_5" type="revolute">
    <parent link="link_4"/>
    <child link="link_5"/>
    <origin xyz="0.058382 0.033858 -0.001709" rpy="0 0 0"/>
    <axis xyz="0.000000 1.000000 0.000000"/>
    <limit lower="-2.0071" upper="2.0071" effort="100" velocity="1"/>
  </joint>
  <joint name="joint_6" type="revolute">
    <parent link="link_5"/>
    <child link="link_6"/>
    <origin xyz="0.000000 0.000000 0.000000" rpy="0 0 0"/>
    <axis xyz="1.000000 0.000000 0.000000"/>
    <limit lower="-3.1416" upper="3.1416" effort="100" velocity="1"/>
  </joint>
</robot>
