<?xml version="1.0"?>
<robot name="Meca500-R3">
  <link name="base_link">
    <visual>
      <geometry>
        <mesh filename="stl_files/A0.stl" scale="0.001 0.001 0.001"/>
      </geometry>
    </visual>
  </link>
  <link name="link_1">
    <visual>
      <origin xyz="-0.000087 0.000048 -0.001030" rpy="0 0 0"/>
      <geometry>
        <mesh filename="stl_files/A1.stl" scale="0.001 0.001 0.001"/>
      </geometry>
    </visual>
  </link>
  <link name="link_2">
    <visual>
      <origin xyz="-0.001760 0.032560 0.000553" rpy="0 0 0"/>
      <geometry>
        <mesh filename="stl_files/A2.stl" scale="0.001 0.001 0.001"/>
      </geometry>
    </visual>
  </link>
  <link name="link_3">
    <visual>
      <origin xyz="-0.000491 0.011082 0.040056" rpy="0 0 0"/>
      <geometry>
        <mesh filename="stl_files/A3_4.stl" scale="0.001 0.001 0.001"/>
      </geometry>
    </visual>
  </link>
  <link name="link_4">
    <visual>
      <origin xyz="-0.000005 0.004871 -0.000093" rpy="0 0 0"/>
      <geometry>
        <mesh filename="stl_files/A5.stl" scale="0.001 0.001 0.001"/>
      </geometry>
    </visual>
  </link>
  <link name="link_5"/>
  <link name="link_6">
    <visual>
      <origin xyz="-0.069465 0.000047 -0.000321" rpy="0 0 0"/>
      <geometry>
        <mesh filename="stl_files/A6.stl" scale="0.001 0.001 0.001"/>
      </geometry>
    </visual>
  </link>
  <joint name="joint_1" type="revolute">
    <parent link="base_link"/>
    <child link="link_1"/>
    <origin xyz="0 0 0.093000" rpy="0 0 0"/>
    <axis xyz="0 0 1"/>
    <limit lower="-3.054" upper="3.054" effort="100" velocity="1"/>
  </joint>
  <joint name="joint_2" type="revolute">
    <parent link="link_1"/>
    <child link="link_2"/>
    <origin xyz="0 0 0.042000" rpy="0 0 0"/>
    <axis xyz="0 1 0"/>
    <limit lower="-1.2217" upper="1.5708" effort="100" velocity="1"/>
  </joint>
  <joint name="joint_3" type="revolute">
    <parent link="link_2"/>
    <child link="link_3"/>
    <origin xyz="0 0 0.135000" rpy="0 0 0"/>
    <axis xyz="0 1 0"/>
    <limit lower="-2.3562" upper="1.2217" effort="100" velocity="1"/>
  </joint>
  <joint name="joint_4" type="revolute">
    <parent link="link_3"/>
    <child link="link_4"/>
    <origin xyz="0.062000 0 0.038000" rpy="0 0 0"/>
    <axis xyz="1 0 0"/>
    <limit lower="-2.9671" upper="2.9671" effort="100" velocity="1"/>
  </joint>
  <joint name="joint_5" type="revolute">
    <parent link="link_4"/>
    <child link="link_5"/>
    <origin xyz="0.055000 0 0" rpy="0 0 0"/>
    <axis xyz="0 1 0"/>
    <limit lower="-2.0071" upper="2.0071" effort="100" velocity="1"/>
  </joint>
  <joint name="joint_6" type="revolute">
    <parent link="link_5"/>
    <child link="link_6"/>
    <origin xyz="0 0 0" rpy="0 0 0"/>
    <axis xyz="1 0 0"/>
    <limit lower="-3.1416" upper="3.1416" effort="100" velocity="1"/>
  </joint>
</robot>
